Workbook

Sheet 0. Start Here
A1: START HERE
A2: You do not need to understand accounting to use this. Fill eight numbers and read the verdict.
A4: WHAT THIS IS
A5: A CFO in a spreadsheet. You type what your business earned and spent. It tells you whether you are making money, whether each order makes money, how long your cash lasts, and what to fix first.
A7: THREE STEPS
A8: 1 | B8: Go to the sheet '1. Setup'. Type over the YELLOW cells only.
B9: Everything that is not yellow calculates itself. You cannot break it by typing in yellow.
A10: 2 | B10: Start with the eight numbers marked START HERE in column C.
B11: The other rows are already filled with example numbers. Replace them as you find them; the dashboard works before you finish.
A12: 3 | B12: Read '2. Dashboard' from the top.
B13: The coloured banner names your single biggest problem in one sentence.
A15: THE EIGHT NUMBERS YOU REALLY NEED
A16: On '1. Setup' | B16: What it means in plain words | F16: Where to find it
A17: Gross Revenue | B17: Everything customers paid you, before refunds. | F17: Your sales report or bank deposits
A18: Product / Material (LANDED) | B18: What the goods cost you delivered to your door - price plus freight plus duty, not the invoice alone. | F18: Supplier invoices plus shipping and customs
A19: Outbound Shipping | B19: Courier cost you actually pay, after what the customer covers. | F19: Courier bill
A20: Advertising Spend | B20: Every platform added together. | F20: Meta, Google, TikTok billing
A21: Salaries (non-production) | B21: People who are paid whether or not you sell anything. | F21: Payroll
A22: Rent | B22: Shop, office or warehouse. | F22: Rent receipt
A23: Number of Orders | B23: How many orders in the period. This turns totals into per-order economics. | F23: Order dashboard
A24: Cash & Bank (closing) | B24: What is actually in the bank on the last day. | F24: Bank statement
A26: WHAT EACH SHEET DOES
A27: 1. Setup | B27: Where you type. Yellow cells only.
A28: 2. Dashboard | B28: The answer. Profit, unit economics, cash, runway, verdict.
A29: 3. Scenarios | B29: What if sales fall 25%? What if ads get cheaper?
A30: 4. Trend | B30: Twelve months side by side. Is it getting better or worse?
A31: Ref | B31: The 34-currency table. You do not need to touch it.
A32: Signature | B32: Who built this. Locked.
A34: READ THIS BEFORE YOU TRUST THE NUMBER
A35: Profit is not cash. You can show a profit here and still have an empty bank account, because loan principal, owner drawings and stock purchases spend cash without appearing as costs. If the profit line and your bank balance disagree, believe the bank.
A37: বাংলা: শুধু হলুদ ঘরগুলোতে আপনার সংখ্যা লিখুন। বাকি সব নিজে হিসাব হয়ে যাবে। '২. Dashboard' শীটে গিয়ে উপরের রঙিন লাইনটা পড়ুন — ওখানে আপনার সবচেয়ে বড় সমস্যাটা এক লাইনে লেখা থাকবে।
A39: ◆ Md Kamrul Hasan · https://github.com/Kamrul5242 · Digital Signature MKH-EBIC-2.2.2 · Attribution required under MIT License

Sheet 1. Setup
A1: CFO DASHBOARD · SETUP & INPUTS
A2: Fill ONLY the yellow cells. Everything else calculates automatically.
A4: CURRENCY
A5: Select currency | B5: BDT
A6: Symbol (auto) | B6: =IFERROR(INDEX(Ref!$B$2:$B$35,MATCH($B$5,Ref!$A$2:$A$35,0)),"?")
A7: Currency name (auto) | B7: =IFERROR(INDEX(Ref!$C$2:$C$35,MATCH($B$5,Ref!$A$2:$A$35,0)),"Unknown")
A8: Reporting period | B8: 2026-03 (monthly)
A10: INCOME · enter your numbers
A11: Line item | B11: Amount | C11: Note
A12: Gross Revenue | B12: 920000 | C12: ◀ START HERE
A13: Returns & Refunds | B13: 70000 | C13: Enter positive
A14: Discounts Given | B14: 0
A15: NET REVENUE | B15: =B12-B13-B14
A17: COST OF GOODS SOLD
A18: Line item | B18: Amount | C18: Note
A19: Product / Material (LANDED) | B19: 380000 | C19: ◀ START HERE
A20: Direct Labour | B20: 40000 | C20: Production staff only
A21: Packaging | B21: 22000
A22: TOTAL COGS | B22: =SUM(B19:B21)
A24: OTHER VARIABLE COSTS · the ones founders forget
A25: Line item | B25: Amount | C25: Note
A26: Outbound Shipping | B26: 102000 | C26: ◀ START HERE
A27: Payment Gateway Fees | B27: 21250 | C27: % + fixed
A28: Marketplace Commission | B28: 0
A29: RTO / Failed Delivery | B29: 0 | C29: Two-way shipping loss
A30: TOTAL OTHER VARIABLE | B30: =SUM(B26:B29)
A32: OPERATING EXPENSES · fixed
A33: Line item | B33: Amount | C33: Note
A34: Advertising Spend | B34: 240000 | C34: ◀ START HERE
A35: Salaries (non-production) | B35: 95000 | C35: ◀ START HERE
A36: Owner Compensation | B36: 40000 | C36: Market rate even if unpaid
A37: Rent | B37: 25000 | C37: ◀ START HERE
A38: Software & Subscriptions | B38: 8000
A39: Other Operating | B39: 12000
A40: Depreciation & Amortization | B40: 0 | C40: Non-cash
A41: TOTAL OPEX | B41: =SUM(B34:B40)
A43: BELOW THE LINE · and cash-only items
A44: Line item | B44: Amount | C44: Note
A45: Interest Expense | B45: 12000 | C45: P&L item
A46: Tax | B46: 0
...

Sheet 2. Dashboard
A1: EXECUTIVE DASHBOARD
A2: Live from Setup. Change any input and every figure here updates.
A3: =""&'1. Setup'!$B$6&" · Period: "&'1. Setup'!$B$8
A5: KEY NUMBERS | E5: UNIT ECONOMICS
A6: Metric | B6: Value | C6: Status | E6: Metric | F6: Value
A7: Net Revenue | B7: ='1. Setup'!$B$15 | C7: =IF(B7>0,"OK",IF(B7=0,"FLAT","LOSS")) | E7: AOV | F7: =IFERROR('1. Setup'!$B$15/'1. Setup'!$B$53,0)
A8: Gross Profit | B8: ='1. Setup'!$B$15-'1. Setup'!$B$22 | C8: =IF(B8>0,"OK",IF(B8=0,"FLAT","LOSS")) | E8: Blended CAC | F8: =IFERROR('1. Setup'!$B$34/'1. Setup'!$B$54,0)
A9: Contribution (pre-ad) | B9: ='1. Setup'!$B$15-'1. Setup'!$B$22-'1. Setup'!$B$30 | C9: =IF(B9>0,"OK",IF(B9=0,"FLAT","LOSS")) | E9: CM per order | F9: =IFERROR(('1. Setup'!$B$15-'1. Setup'!$B$22-'1. Setup'!$B$30-'1. Setup'!$B$34)/'1. Setup'!$B$53,0)
A10: CM after Ads | B10: ='1. Setup'!$B$15-'1. Setup'!$B$22-'1. Setup'!$B$30-'1. Setup'!$B$34 | C10: =IF(B10>0,"OK",IF(B10=0,"FLAT","LOSS")) | E10: CM ratio (pre-ad) | F10: =IFERROR(('1. Setup'!$B$15-'1. Setup'!$B$22-'1. Setup'!$B$30)/'1. Setup'!$B$15,0)
A11: Operating Profit | B11: ='1. Setup'!$B$15-'1. Setup'!$B$22-'1. Setup'!$B$30-'1. Setup'!$B$41 | C11: =IF(B11>0,"OK",IF(B11=0,"FLAT","LOSS")) | E11: Break-even ROAS | F11: =IFERROR('1. Setup'!$B$15/('1. Setup'!$B$15-'1. Setup'!$B$22-'1. Setup'!$B$30),0)
A12: Net Profit | B12: ='1. Setup'!$B$15-'1. Setup'!$B$22-'1. Setup'!$B$30-'1. Setup'!$B$41-'1. Setup'!$B$45-'1. Setup'!$B$46 | C12: =IF(B12>0,"OK",IF(B12=0,"FLAT","LOSS")) | E12: Actual ROAS (blended) | F12: =IFERROR('1. Setup'!$B$15/'1. Setup'!$B$34,0)
A13: Gross Margin | B13: =IFERROR(('1. Setup'!$B$15-'1. Setup'!$B$22)/'1. Setup'!$B$15,0) | C13: =IF(B13>0,"OK",IF(B13=0,"FLAT","LOSS")) | E13: ROAS headroom | F13: =IFERROR('1. Setup'!$B$15/'1. Setup'!$B$34-'1. Setup'!$B$15/('1. Setup'!$B$15-'1. Setup'!$B$22-'1. Setup'!$B$30),0)
A14: Net Margin | B14: =IFERROR(('1. Setup'!$B$15-'1. Setup'!$B$22-'1. Setup'!$B$30-'1. Setup'!$B$41-'1. Setup'!$B$45-'1. Setup'!$B$46)/'1. Setup'!$B$15,0) | C14: =IF(B14>0,"OK",IF(B14=0,"FLAT","LOSS")) | E14: Repeat rate | F14: =IFERROR('1. Setup'!$B$55/('1. Setup'!$B$54+'1. Setup'!$B$55),0)
E15: Churn rate | F15: =IFERROR('1. Setup'!$B$56/'1. Setup'!$B$57,0)
A16: CASH · RUNWAY | E16: LIQUIDITY & CASH CYCLE
A17: Metric | B17: Value | C17: Status | E17: Metric | F17: Value
A18: Operating Cash Flow (approx) | B18: =('1. Setup'!$B$15-'1. Setup'!$B$22-'1. Setup'!$B$30-'1. Setup'!$B$41-'1. Setup'!$B$45-'1. Setup'!$B$46)+'1. Setup'!$B$40 | C18: =IF(ISTEXT(B18),"OK",IF(B18>=0,"OK","LOSS")) | E18: Current Ratio | F18: =IFERROR('1. Setup'!$B$63/'1. Setup'!$B$64,0)
A19: Cash out below the line | B19: ='1. Setup'!$B$47+'1. Setup'!$B$48+'1. Setup'!$B$49 | C19: =IF(ISTEXT(B19),"OK",IF(B19>=0,"OK","LOSS")) | E19: Quick Ratio | F19: =IFERROR(('1. Setup'!$B$63-'1. Setup'!$B$60)/'1. Setup'!$B$64,0)
A20: Net Cash Change | B20: =('1. Setup'!$B$15-'1. Setup'!$B$22-'1. Setup'!$B$30-'1. Setup'!$B$41-'1. Setup'!$B$45-'1. Setup'!$B$46)+'1. Setup'!$B$40-'1. Setup'!$B$47-'1. Setup'!$B$48-'1. Setup'!$B$49 | C20: =IF(ISTEXT(B20),"OK",IF(B20>=0,"OK","LOSS")) | E20: Debt / Equity | F20: =IFERROR('1. Setup'!$B$62/'1. Setup'!$B$65,0)
A21: Monthly Net Burn | B21: =MAX(0,-(('1. Setup'!$B$15-'1. Setup'!$B$22-'1. Setup'!$B$30-'1. Setup'!$B$41-'1. Setup'!$B$45-'1. Setup'!$B$46)+'1. Setup'!$B$40-'1. Setup'!$B$47-'1. Setup'!$B$48-'1. Setup'!$B$49)) | C21: =IF(ISTEXT(B21),"OK",IF(B21>=0,"OK","LOSS")) | E21: Interest Coverage | F21: =IFERROR(('1. Setup'!$B$15-'1. Setup'!$B$22-'1. Setup'!$B$30-'1. Setup'!$B$41)/'1. Setup'!$B$45,0)
A22: Runway (months) | B22: =IF(MAX(0,-(('1. Setup'!$B$15-'1. Setup'!$B$22-'1. Setup'!$B$30-'1. Setup'!$B$41-'1. Setup'!$B$45-'1. Setup'!$B$46)+'1. Setup'!$B$40-'1. Setup'!$B$47-'1. Setup'!$B$48-'1. Setup'!$B$49))=0,"cash positive",'1. Setup'!$B$58/MAX(1,-(('1. Setup'!$B$15-'1. Setup'!$B$22-'1. Setup'!$B$30-'1. Setup'!$B$41-'1. Setup'!$B$45-'1. Setup'!$B$46)+'1. Setup'!$B$40-'1. Setup'!$B$47-'1. Setup'!$B$48-'1. Setup'!$B$49))) | C22: =IF(ISTEXT(B22),"OK",IF(B22>=0,"OK","LOSS")) | E22: DIO (days) | F22: =IFERROR('1. Setup'!$B$60/'1. Setup'!$B$22*'1. Setup'!$B$66,0)
E23: DSO (days) | F23: =IFERROR('1. Setup'!$B$59/'1. Setup'!$B$15*'1. Setup'!$B$66,0)
E24: DPO (days) | F24: =IFERROR('1. Setup'!$B$61/'1. Setup'!$B$22*'1. Setup'!$B$66,0)
E25: Cash Conversion Cycle | F25: =IFERROR('1. Setup'!$B$60/'1. Setup'!$B$22*'1. Setup'!$B$66+'1. Setup'!$B$59/'1. Setup'!$B$15*'1. Setup'!$B$66-'1. Setup'!$B$61/'1. Setup'!$B$22*'1. Setup'!$B$66,0)
A27: BREAK-EVEN
A28: Fixed costs (OPEX excl. ads) | B28: ='1. Setup'!$B$41-'1. Setup'!$B$34
A29: CM ratio (pre-ad) | B29: =IFERROR(('1. Setup'!$B$15-'1. Setup'!$B$22-'1. Setup'!$B$30)/'1. Setup'!$B$15,0)
A30: Break-even revenue | B30: =IFERROR(B28/B29,0)
A31: Break-even orders | B31: =IFERROR(B30/IFERROR('1. Setup'!$B$15/'1. Setup'!$B$53,1),0)
A32: Margin of safety | B32: =IFERROR(('1. Setup'!$B$15-B30)/'1. Setup'!$B$15,0)
A34: VERDICT
A35: =IF(B10<0,"BROKEN UNIT ECONOMICS — contribution after ads is negative and actual ROAS is below break-even ROAS. Every order loses money before fixed costs are even counted. Stop scaling; fix pricing, CAC, or COGS first.",IF(B12<0,"NET LOSS FROM OVERHEAD — each order is profitable after ads, but fixed costs, interest, or tax exceed that contribution. Fix overhead, not the product.","PROFITABLE — protect margin and scale toward the next constraint."))
A56: ◆ Md Kamrul Hasan · https://github.com/Kamrul5242 · Digital Signature MKH-EBIC-2.2.2 · Attribution required under MIT License

Sheet 3. Scenarios
A1: SCENARIO MODEL
A2: Edit the yellow drivers. Conservative / Base / Aggressive recalculate live.
A4: DRIVERS
A5: Driver | B5: Conservative | C5: Base | D5: Aggressive
A6: Revenue change | B6: -0.25 | C6: 0 | D6: 0.25
A7: COGS % change | B7: 0.04 | C7: 0 | D7: -0.02
A8: Ad spend change | B8: 0.1 | C8: 0 | D8: 0.2
A9: Fixed cost change | B9: 0.05 | C9: 0 | D9: 0
A11: OUTCOME
A12: Line | B12: Conservative | C12: Base | D12: Aggressive
A13: Net Revenue | B13: ='1. Setup'!$B$15*(1+B6) | C13: ='1. Setup'!$B$15*(1+C6) | D13: ='1. Setup'!$B$15*(1+D6)
A14: COGS | B14: ='1. Setup'!$B$22*(1+B6)*(1+B7) | C14: ='1. Setup'!$B$22*(1+C6)*(1+C7) | D14: ='1. Setup'!$B$22*(1+D6)*(1+D7)
A15: Other variable | B15: ='1. Setup'!$B$30*(1+B6) | C15: ='1. Setup'!$B$30*(1+C6) | D15: ='1. Setup'!$B$30*(1+D6)
A16: Ad spend | B16: ='1. Setup'!$B$34*(1+B8) | C16: ='1. Setup'!$B$34*(1+C8) | D16: ='1. Setup'!$B$34*(1+D8)
A17: Fixed OPEX | B17: =('1. Setup'!$B$41-'1. Setup'!$B$34)*(1+B9) | C17: =('1. Setup'!$B$41-'1. Setup'!$B$34)*(1+C9) | D17: =('1. Setup'!$B$41-'1. Setup'!$B$34)*(1+D9)
A18: Gross Profit | B18: =B13-B14 | C18: =C13-C14 | D18: =D13-D14
A19: Contribution after ads | B19: =B13-B14-B15-B16 | C19: =C13-C14-C15-C16 | D19: =D13-D14-D15-D16
A20: Operating Profit | B20: =B19-B17 | C20: =C19-C17 | D20: =D19-D17
A21: Operating Margin | B21: =IFERROR(B20/B13,0) | C21: =IFERROR(C20/C13,0) | D21: =IFERROR(D20/D13,0)
A22: Verdict | B22: =IF(B20>0,"PROFIT","LOSS") | C22: =IF(C20>0,"PROFIT","LOSS") | D22: =IF(D20>0,"PROFIT","LOSS")
A24: PRICE SENSITIVITY · how much volume can you afford to lose?
A25: Price increase | B25: Max volume loss tolerable
A26: 0.05 | B26: =IFERROR(0.05/(IFERROR(('1. Setup'!$B$15-'1. Setup'!$B$22-'1. Setup'!$B$30)/'1. Setup'!$B$15,0.3)+0.05),0)
A27: 0.1 | B27: =IFERROR(0.1/(IFERROR(('1. Setup'!$B$15-'1. Setup'!$B$22-'1. Setup'!$B$30)/'1. Setup'!$B$15,0.3)+0.1),0)
A28: 0.15 | B28: =IFERROR(0.15/(IFERROR(('1. Setup'!$B$15-'1. Setup'!$B$22-'1. Setup'!$B$30)/'1. Setup'!$B$15,0.3)+0.15),0)
A29: 0.2 | B29: =IFERROR(0.2/(IFERROR(('1. Setup'!$B$15-'1. Setup'!$B$22-'1. Setup'!$B$30)/'1. Setup'!$B$15,0.3)+0.2),0)
A31: ◆ Md Kamrul Hasan · https://github.com/Kamrul5242 · Digital Signature MKH-EBIC-2.2.2 · Attribution required under MIT License

Sheet 4. Trend
A1: 12-MONTH TREND
A2: One column per month. Fill the yellow rows; the rest calculates. A single month cannot tell you whether a business is improving.
A4: Line item | B4: M1 | C4: M2 | D4: M3 | E4: M4 | F4: M5 | G4: M6 | H4: M7 | I4: M8 | J4: M9 | K4: M10 | L4: M11 | M4: M12
A5: Net Revenue
A6: COGS
A7: Variable Costs (shipping, gateway, RTO)
A8: Ad Spend
A9: Fixed Operating Costs
A10: CALCULATED
A11: Contribution | B11: =B5-B6-B7 | C11: =C5-C6-C7 | D11: =D5-D6-D7 | E11: =E5-E6-E7 | F11: =F5-F6-F7 | G11: =G5-G6-G7 | H11: =H5-H6-H7 | I11: =I5-I6-I7 | ... M11: =M5-M6-M7
A12: Contribution Margin % | B12: =IFERROR(B11/B5,"") | C12: =IFERROR(C11/C5,"") | D12: =IFERROR(D11/D5,"") | E12: =IFERROR(E11/E5,"") | F12: =IFERROR(F11/F5,"") | G12: =IFERROR(G11/G5,"") | H12: =IFERROR(H11/H5,"") | I12: =IFERROR(I11/I5,"") | ... M12: =IFERROR(M11/M5,"")
A13: Operating Profit | B13: =B11-B8-B9 | C13: =C11-C8-C9 | D13: =D11-D8-D9 | E13: =E11-E8-E9 | F13: =F11-F8-F9 | G13: =G11-G8-G9 | H13: =H11-H8-H9 | I13: =I11-I8-I9 | ... M13: =M11-M8-M9
A14: Operating Margin % | B14: =IFERROR(B13/B5,"") | C14: =IFERROR(C13/C5,"") | D14: =IFERROR(D13/D5,"") | E14: =IFERROR(E13/E5,"") | F14: =IFERROR(F13/F5,"") | G14: =IFERROR(G13/G5,"") | H14: =IFERROR(H13/H5,"") | I14: =IFERROR(I13/I5,"") | ... M14: =IFERROR(M13/M5,"")
A15: Cumulative Operating Profit | B15: =B13 | C15: =B15+C13 | D15: =C15+D13 | E15: =D15+E13 | F15: =E15+F13 | G15: =F15+G13 | H15: =G15+H13 | I15: =H15+I13 | J15: =I15+J13 | ... M15: =L15+M13
A16: Revenue Growth vs Prior Month % | C16: =IFERROR(C5/B5-1,"") | D16: =IFERROR(D5/C5-1,"") | E16: =IFERROR(E5/D5-1,"") | F16: =IFERROR(F5/E5-1,"") | G16: =IFERROR(G5/F5-1,"") | H16: =IFERROR(H5/G5-1,"") | I16: =IFERROR(I5/H5-1,"") | J16: =IFERROR(J5/I5-1,"") | ... M16: =IFERROR(M5/L5-1,"")
A18: REVENUE AND OPERATING PROFIT BY MONTH
A37: Read the direction, not the level. Three months of falling contribution margin is a structural problem; one month is noise.
A39: ◆ Md Kamrul Hasan · https://github.com/Kamrul5242 · Digital Signature MKH-EBIC-2.2.2 · Attribution required under MIT License

Sheet Ref
A1: Code | B1: Symbol | C1: Name | D1: Decimals
A2: BDT | B2: ৳ | C2: Bangladeshi Taka | D2: 2
A3: INR | B3: ₹ | C3: Indian Rupee | D3: 2
A4: PKR | B4: ₨ | C4: Pakistani Rupee | D4: 2
A5: LKR | B5: Rs | C5: Sri Lankan Rupee | D5: 2
A6: NPR | B6: रू | C6: Nepalese Rupee | D6: 2
A7: USD | B7: $ | C7: US Dollar | D7: 2
A8: EUR | B8: € | C8: Euro | D8: 2
A9: GBP | B9: £ | C9: Pound Sterling | D9: 2
A10: CAD | B10: C$ | C10: Canadian Dollar | D10: 2
A11: AUD | B11: A$ | C11: Australian Dollar | D11: 2
A12: AED | B12: د.إ | C12: UAE Dirham | D12: 2
A13: SAR | B13: SR | C13: Saudi Riyal | D13: 2
... A35: SEK | B35: kr | C35: Swedish Krona | D35: 2

Sheet Signature
A1: DIGITAL SIGNATURE · DO NOT MODIFY
A3: Author | B3: Md Kamrul Hasan
A4: GitHub | B4: https://github.com/Kamrul5242
A5: Skill | B5: entrepreneur-business-intelligence-cfo
A6: Version | B6: 2.2.2
A7: Signature ID | B7: MKH-EBIC-2.2.2
A8: License | B8: MIT — attribution required
A9: Default currency | B9: BDT (all 34 supported)
A10: Notice | B10: This workbook and its formula design are the work of Md Kamrul Hasan. The MIT License permits reuse and modification provided this attribution is retained in all copies and substantial portions.
A12: ◆ Md Kamrul Hasan · https://github.com/Kamrul5242 · Digital Signature MKH-EBIC-2.2.2 · Attribution required under MIT License
